<?xml version="1.0"?>
<robot xmlns:xacro="http://www.ros.org/wiki/xacro"  >

    <xacro:include filename="inertial_macros.xacro"/>

    <material name="white">
            <color rgba="1 1 1 1" />
    </material>

    <material name="red">
        <color rgba="1 0 0 1" />
    </material>

    <material name="black">
        <color rgba="0 0 0 1" />
    </material>

    <material name="blue">
       <color rgba="0.2 0.2 1 1" />
    </material>

    <!-- BASE LINK -->

    <link name ="base_link">

    </link>

    <!-- BASE_FOOTPRINT LINK -->

    <joint name="base_footprint_joint" type="fixed">
        <parent link="base_link"/>
        <child link="base_footprint"/>
        <origin xyz="0 0 0" rpy="0 0 0"/>
    </joint>

    <link name="base_footprint">
    </link>

    <!-- CHASSIS LINK -->

    <joint name="chassis_joint" type="fixed">
        <parent link="base_link"/>
        <child link="chassis"/>
        <origin xyz="-0.065 0 0"/>
    </joint>

    <link name="chassis">
        <visual>
            <origin xyz="0.165 0 0.075"/>
            <geometry>
                <box size="0.33 0.19 0.15"/>
            </geometry>
            <material name="red"/>
        </visual>
        <collision>
            <origin xyz="0.165 0 0.075"/>
            <geometry>
                <box size="0.33 0.19 0.15"/>
            </geometry>
        </collision>
        <xacro:inertial_box mass="0.8" x="0.33" y="0.19" z="0.15">
            <origin xyz="0.165 0 0.075" rpy="0 0 0"/>
        </xacro:inertial_box>
    </link>

    <gazebo reference="chassis">
        <material>Gazebo/Red</material>
    </gazebo>

    <!-- LEFT WHEEL LINK -->

    <joint name ="left_wheel_joint" type ="continuous">
        <parent link = "base_link"/>
        <child link = "left_wheel"/>
        <origin xyz="0 0.1084 0" rpy="-${pi/2} 0 0"/>
        <axis xyz="0 0 1"/>
    </joint>

    <link name="left_wheel">
        <visual>
            <geometry>
                <cylinder radius="0.0325" length="0.027"/>
            </geometry>
            <material name="black"/>
        </visual>
        <collision>
            <geometry>
                <sphere radius="0.0325"/>
            </geometry>
        </collision>
        <xacro:inertial_cylinder mass="0.2" length="0.027" radius="0.0325">
            <origin xyz="0 0 0" rpy="0 0 0"/>
        </xacro:inertial_cylinder>
    </link>

    <gazebo reference = "left_wheel">
        <material>Gazebo/Black</material>
    </gazebo>

        <!-- RIGHT WHEEL LINK -->

        <joint name ="right_wheel_joint" type ="continuous">
            <parent link = "base_link"/>
            <child link = "right_wheel"/>
            <origin xyz="0 -0.1084 0" rpy="${pi/2} 0 0"/>
            <axis xyz="0 0 -1"/>
        </joint>
    
        <link name="right_wheel">
            <visual>
                <geometry>
                    <cylinder radius="0.0325" length="0.027"/>
                </geometry>
                <material name="black"/>
            </visual>
            <collision>
                <geometry>
                    <sphere radius="0.0325"/>
                </geometry>
            </collision>
            <xacro:inertial_cylinder mass="0.2" length="0.027" radius="0.0325">
            <origin xyz="0 0 0" rpy="0 0 0"/>
        </xacro:inertial_cylinder>
        </link>

        <gazebo reference = "right_wheel">
            <material>Gazebo/Black</material>
        </gazebo>

        <!-- CASTER WHEEL LINK -->

        <joint name="caster_wheel_joint" type="fixed">
            <parent link="chassis"/>
            <child link="caster_wheel"/>
            <origin xyz="0.27 0 0"/>
        </joint>

        <link name="caster_wheel">
            <visual>
                <geometry>
                    <sphere radius="0.0325"/>
                </geometry>
                <material name="black"/>
            </visual>
            <collision>
                <geometry>
                    <sphere radius="0.0325"/>
                </geometry>
            </collision>
            <xacro:inertial_sphere mass="0.3" radius="0.0325">
                <origin xyz="0 0 0" rpy="0 0 0"/>
            </xacro:inertial_sphere>
        </link>

        <gazebo reference = "caster_wheel">
            <material>Gazebo/Black</material>
            <mu1 value="0.005"/>
            <mu2 value="0.005"/>
        </gazebo>

</robot>